Watching for file changes with StatReloader
[24/Jul/2021 04:53:15] "GET / HTTP/1.1" 200 16348
[24/Jul/2021 04:53:15] "GET /static/admin/css/fonts.css HTTP/1.1" 304 0
[24/Jul/2021 04:53:15] "GET /static/admin/fonts/Roboto-Regular-webfont.woff HTTP/1.1" 304 0
[24/Jul/2021 04:53:16] "GET /static/admin/fonts/Roboto-Light-webfont.woff HTTP/1.1" 304 0
[24/Jul/2021 04:53:16] "GET /static/admin/fonts/Roboto-Bold-webfont.woff HTTP/1.1" 304 0
Not Found: /index
[24/Jul/2021 04:54:41] "GET /index HTTP/1.1" 404 2009
/projects/book_store/Book_Store/Book_Store/urls.py changed, reloading.
Performing system checks...

System check identified no issues (0 silenced).
July 24, 2021 - 04:53:09
Django version 2.2.24, using settings 'Book_Store.settings'
Starting development server at http://0.0.0.0:8000/
Quit the server with CONTROL-C.
Watching for file changes with StatReloader
/projects/book_store/Book_Store/Book_Store/urls.py changed, reloading.
Performing system checks...

System check identified no issues (0 silenced).
July 24, 2021 - 04:54:59
Django version 2.2.24, using settings 'Book_Store.settings'
Starting development server at http://0.0.0.0:8000/
Quit the server with CONTROL-C.
Watching for file changes with StatReloader
Exception in thread django-main-thread:
Traceback (most recent call last):
  File "/usr/lib/python3.5/threading.py", line 914, in _bootstrap_inner
    self.run()
  File "/usr/lib/python3.5/threading.py", line 862, in run
    self._target(*self._args, **self._kwargs)
  File "/home/user/.local/lib/python3.5/site-packages/django/utils/autoreload.py", line 54, in wrapper
    fn(*args, **kwargs)
  File "/home/user/.local/lib/python3.5/site-packages/django/core/management/commands/runserver.py", line 117, in inner_run
    self.check(display_num_errors=True)
  File "/home/user/.local/lib/python3.5/site-packages/django/core/management/base.py", line 390, in check
    include_deployment_checks=include_deployment_checks,
  File "/home/user/.local/lib/python3.5/site-packages/django/core/management/base.py", line 377, in _run_checks
    return checks.run_checks(**kwargs)
  File "/home/user/.local/lib/python3.5/site-packages/django/core/checks/registry.py", line 72, in run_checks
    new_errors = check(app_configs=app_configs)
  File "/home/user/.local/lib/python3.5/site-packages/django/core/checks/urls.py", line 40, in check_url_namespaces_unique
    all_namespaces = _load_all_namespaces(resolver)
  File "/home/user/.local/lib/python3.5/site-packages/django/core/checks/urls.py", line 57, in _load_all_namespaces
    url_patterns = getattr(resolver, 'url_patterns', [])
  File "/home/user/.local/lib/python3.5/site-packages/django/utils/functional.py", line 80, in __get__
    res = instance.__dict__[self.name] = self.func(instance)
  File "/home/user/.local/lib/python3.5/site-packages/django/urls/resolvers.py", line 584, in url_patterns
    patterns = getattr(self.urlconf_module, "urlpatterns", self.urlconf_module)
  File "/home/user/.local/lib/python3.5/site-packages/django/utils/functional.py", line 80, in __get__
    res = instance.__dict__[self.name] = self.func(instance)
  File "/home/user/.local/lib/python3.5/site-packages/django/urls/resolvers.py", line 577, in urlconf_module
    return import_module(self.urlconf_name)
  File "/usr/lib/python3.5/importlib/__init__.py", line 126, in import_module
    return _bootstrap._gcd_import(name[level:], package, level)
  File "<frozen importlib._bootstrap>", line 986, in _gcd_import
  File "<frozen importlib._bootstrap>", line 969, in _find_and_load
  File "<frozen importlib._bootstrap>", line 958, in _find_and_load_unlocked
  File "<frozen importlib._bootstrap>", line 673, in _load_unlocked
  File "<frozen importlib._bootstrap_external>", line 665, in exec_module
  File "<frozen importlib._bootstrap>", line 222, in _call_with_frames_removed
  File "/projects/book_store/Book_Store/Book_Store/urls.py", line 21, in <module>
    path('')
TypeError: _path() missing 1 required positional argument: 'view'

/projects/book_store/Book_Store/Book_Store/urls.py changed, reloading.
Performing system checks...

Watching for file changes with StatReloader
Exception in thread django-main-thread:
Traceback (most recent call last):
  File "/usr/lib/python3.5/threading.py", line 914, in _bootstrap_inner
    self.run()
  File "/usr/lib/python3.5/threading.py", line 862, in run
    self._target(*self._args, **self._kwargs)
  File "/home/user/.local/lib/python3.5/site-packages/django/utils/autoreload.py", line 54, in wrapper
    fn(*args, **kwargs)
  File "/home/user/.local/lib/python3.5/site-packages/django/core/management/commands/runserver.py", line 117, in inner_run
    self.check(display_num_errors=True)
  File "/home/user/.local/lib/python3.5/site-packages/django/core/management/base.py", line 390, in check
    include_deployment_checks=include_deployment_checks,
  File "/home/user/.local/lib/python3.5/site-packages/django/core/management/base.py", line 377, in _run_checks
    return checks.run_checks(**kwargs)
  File "/home/user/.local/lib/python3.5/site-packages/django/core/checks/registry.py", line 72, in run_checks
    new_errors = check(app_configs=app_configs)
  File "/home/user/.local/lib/python3.5/site-packages/django/core/checks/urls.py", line 40, in check_url_namespaces_unique
    all_namespaces = _load_all_namespaces(resolver)
  File "/home/user/.local/lib/python3.5/site-packages/django/core/checks/urls.py", line 57, in _load_all_namespaces
    url_patterns = getattr(resolver, 'url_patterns', [])
  File "/home/user/.local/lib/python3.5/site-packages/django/utils/functional.py", line 80, in __get__
    res = instance.__dict__[self.name] = self.func(instance)
  File "/home/user/.local/lib/python3.5/site-packages/django/urls/resolvers.py", line 584, in url_patterns
    patterns = getattr(self.urlconf_module, "urlpatterns", self.urlconf_module)
  File "/home/user/.local/lib/python3.5/site-packages/django/utils/functional.py", line 80, in __get__
    res = instance.__dict__[self.name] = self.func(instance)
  File "/home/user/.local/lib/python3.5/site-packages/django/urls/resolvers.py", line 577, in urlconf_module
    return import_module(self.urlconf_name)
  File "/usr/lib/python3.5/importlib/__init__.py", line 126, in import_module
    return _bootstrap._gcd_import(name[level:], package, level)
  File "<frozen importlib._bootstrap>", line 986, in _gcd_import
  File "<frozen importlib._bootstrap>", line 969, in _find_and_load
  File "<frozen importlib._bootstrap>", line 958, in _find_and_load_unlocked
  File "<frozen importlib._bootstrap>", line 673, in _load_unlocked
  File "<frozen importlib._bootstrap_external>", line 665, in exec_module
  File "<frozen importlib._bootstrap>", line 222, in _call_with_frames_removed
  File "/projects/book_store/Book_Store/Book_Store/urls.py", line 21, in <module>
    path('', )
TypeError: _path() missing 1 required positional argument: 'view'

/projects/book_store/Book_Store/Book_Store/urls.py changed, reloading.
Performing system checks...

Watching for file changes with StatReloader
Exception in thread django-main-thread:
Traceback (most recent call last):
  File "/usr/lib/python3.5/threading.py", line 914, in _bootstrap_inner
    self.run()
  File "/usr/lib/python3.5/threading.py", line 862, in run
    self._target(*self._args, **self._kwargs)
  File "/home/user/.local/lib/python3.5/site-packages/django/utils/autoreload.py", line 54, in wrapper
    fn(*args, **kwargs)
  File "/home/user/.local/lib/python3.5/site-packages/django/core/management/commands/runserver.py", line 117, in inner_run
    self.check(display_num_errors=True)
  File "/home/user/.local/lib/python3.5/site-packages/django/core/management/base.py", line 390, in check
    include_deployment_checks=include_deployment_checks,
  File "/home/user/.local/lib/python3.5/site-packages/django/core/management/base.py", line 377, in _run_checks
    return checks.run_checks(**kwargs)
  File "/home/user/.local/lib/python3.5/site-packages/django/core/checks/registry.py", line 72, in run_checks
    new_errors = check(app_configs=app_configs)
  File "/home/user/.local/lib/python3.5/site-packages/django/core/checks/urls.py", line 40, in check_url_namespaces_unique
    all_namespaces = _load_all_namespaces(resolver)
  File "/home/user/.local/lib/python3.5/site-packages/django/core/checks/urls.py", line 57, in _load_all_namespaces
    url_patterns = getattr(resolver, 'url_patterns', [])
  File "/home/user/.local/lib/python3.5/site-packages/django/utils/functional.py", line 80, in __get__
    res = instance.__dict__[self.name] = self.func(instance)
  File "/home/user/.local/lib/python3.5/site-packages/django/urls/resolvers.py", line 584, in url_patterns
    patterns = getattr(self.urlconf_module, "urlpatterns", self.urlconf_module)
  File "/home/user/.local/lib/python3.5/site-packages/django/utils/functional.py", line 80, in __get__
    res = instance.__dict__[self.name] = self.func(instance)
  File "/home/user/.local/lib/python3.5/site-packages/django/urls/resolvers.py", line 577, in urlconf_module
    return import_module(self.urlconf_name)
  File "/usr/lib/python3.5/importlib/__init__.py", line 126, in import_module
    return _bootstrap._gcd_import(name[level:], package, level)
  File "<frozen importlib._bootstrap>", line 986, in _gcd_import
  File "<frozen importlib._bootstrap>", line 969, in _find_and_load
  File "<frozen importlib._bootstrap>", line 958, in _find_and_load_unlocked
  File "<frozen importlib._bootstrap>", line 673, in _load_unlocked
  File "<frozen importlib._bootstrap_external>", line 665, in exec_module
  File "<frozen importlib._bootstrap>", line 222, in _call_with_frames_removed
  File "/projects/book_store/Book_Store/Book_Store/urls.py", line 21, in <module>
    path('', viewd)
NameError: name 'viewd' is not defined

/projects/book_store/Book_Store/Book_Store/urls.py changed, reloading.
Performing system checks...

Watching for file changes with StatReloader
Exception in thread django-main-thread:
Traceback (most recent call last):
  File "/usr/lib/python3.5/threading.py", line 914, in _bootstrap_inner
    self.run()
  File "/usr/lib/python3.5/threading.py", line 862, in run
    self._target(*self._args, **self._kwargs)
  File "/home/user/.local/lib/python3.5/site-packages/django/utils/autoreload.py", line 54, in wrapper
    fn(*args, **kwargs)
  File "/home/user/.local/lib/python3.5/site-packages/django/core/management/commands/runserver.py", line 117, in inner_run
    self.check(display_num_errors=True)
  File "/home/user/.local/lib/python3.5/site-packages/django/core/management/base.py", line 390, in check
    include_deployment_checks=include_deployment_checks,
  File "/home/user/.local/lib/python3.5/site-packages/django/core/management/base.py", line 377, in _run_checks
    return checks.run_checks(**kwargs)
  File "/home/user/.local/lib/python3.5/site-packages/django/core/checks/registry.py", line 72, in run_checks
    new_errors = check(app_configs=app_configs)
  File "/home/user/.local/lib/python3.5/site-packages/django/core/checks/urls.py", line 40, in check_url_namespaces_unique
    all_namespaces = _load_all_namespaces(resolver)
  File "/home/user/.local/lib/python3.5/site-packages/django/core/checks/urls.py", line 57, in _load_all_namespaces
    url_patterns = getattr(resolver, 'url_patterns', [])
  File "/home/user/.local/lib/python3.5/site-packages/django/utils/functional.py", line 80, in __get__
    res = instance.__dict__[self.name] = self.func(instance)
  File "/home/user/.local/lib/python3.5/site-packages/django/urls/resolvers.py", line 584, in url_patterns
    patterns = getattr(self.urlconf_module, "urlpatterns", self.urlconf_module)
  File "/home/user/.local/lib/python3.5/site-packages/django/utils/functional.py", line 80, in __get__
    res = instance.__dict__[self.name] = self.func(instance)
  File "/home/user/.local/lib/python3.5/site-packages/django/urls/resolvers.py", line 577, in urlconf_module
    return import_module(self.urlconf_name)
  File "/usr/lib/python3.5/importlib/__init__.py", line 126, in import_module
    return _bootstrap._gcd_import(name[level:], package, level)
  File "<frozen importlib._bootstrap>", line 986, in _gcd_import
  File "<frozen importlib._bootstrap>", line 969, in _find_and_load
  File "<frozen importlib._bootstrap>", line 958, in _find_and_load_unlocked
  File "<frozen importlib._bootstrap>", line 673, in _load_unlocked
  File "<frozen importlib._bootstrap_external>", line 665, in exec_module
  File "<frozen importlib._bootstrap>", line 222, in _call_with_frames_removed
  File "/projects/book_store/Book_Store/Book_Store/urls.py", line 21, in <module>
    path('', views.home)
NameError: name 'views' is not defined

/projects/book_store/Book_Store/Book_Store/urls.py changed, reloading.
Performing system checks...

Watching for file changes with StatReloader
Exception in thread django-main-thread:
Traceback (most recent call last):
  File "/usr/lib/python3.5/threading.py", line 914, in _bootstrap_inner
    self.run()
  File "/usr/lib/python3.5/threading.py", line 862, in run
    self._target(*self._args, **self._kwargs)
  File "/home/user/.local/lib/python3.5/site-packages/django/utils/autoreload.py", line 54, in wrapper
    fn(*args, **kwargs)
  File "/home/user/.local/lib/python3.5/site-packages/django/core/management/commands/runserver.py", line 117, in inner_run
    self.check(display_num_errors=True)
  File "/home/user/.local/lib/python3.5/site-packages/django/core/management/base.py", line 390, in check
    include_deployment_checks=include_deployment_checks,
  File "/home/user/.local/lib/python3.5/site-packages/django/core/management/base.py", line 377, in _run_checks
    return checks.run_checks(**kwargs)
  File "/home/user/.local/lib/python3.5/site-packages/django/core/checks/registry.py", line 72, in run_checks
    new_errors = check(app_configs=app_configs)
  File "/home/user/.local/lib/python3.5/site-packages/django/core/checks/urls.py", line 40, in check_url_namespaces_unique
    all_namespaces = _load_all_namespaces(resolver)
  File "/home/user/.local/lib/python3.5/site-packages/django/core/checks/urls.py", line 57, in _load_all_namespaces
    url_patterns = getattr(resolver, 'url_patterns', [])
  File "/home/user/.local/lib/python3.5/site-packages/django/utils/functional.py", line 80, in __get__
    res = instance.__dict__[self.name] = self.func(instance)
  File "/home/user/.local/lib/python3.5/site-packages/django/urls/resolvers.py", line 584, in url_patterns
    patterns = getattr(self.urlconf_module, "urlpatterns", self.urlconf_module)
  File "/home/user/.local/lib/python3.5/site-packages/django/utils/functional.py", line 80, in __get__
    res = instance.__dict__[self.name] = self.func(instance)
  File "/home/user/.local/lib/python3.5/site-packages/django/urls/resolvers.py", line 577, in urlconf_module
    return import_module(self.urlconf_name)
  File "/usr/lib/python3.5/importlib/__init__.py", line 126, in import_module
    return _bootstrap._gcd_import(name[level:], package, level)
  File "<frozen importlib._bootstrap>", line 986, in _gcd_import
  File "<frozen importlib._bootstrap>", line 969, in _find_and_load
  File "<frozen importlib._bootstrap>", line 958, in _find_and_load_unlocked
  File "<frozen importlib._bootstrap>", line 673, in _load_unlocked
  File "<frozen importlib._bootstrap_external>", line 665, in exec_module
  File "<frozen importlib._bootstrap>", line 222, in _call_with_frames_removed
  File "/projects/book_store/Book_Store/Book_Store/urls.py", line 21, in <module>
    path('', views.home),
NameError: name 'views' is not defined

/projects/book_store/Book_Store/Book_Store/urls.py changed, reloading.
Performing system checks...

Watching for file changes with StatReloader
Exception in thread django-main-thread:
Traceback (most recent call last):
  File "/usr/lib/python3.5/threading.py", line 914, in _bootstrap_inner
    self.run()
  File "/usr/lib/python3.5/threading.py", line 862, in run
    self._target(*self._args, **self._kwargs)
  File "/home/user/.local/lib/python3.5/site-packages/django/utils/autoreload.py", line 54, in wrapper
    fn(*args, **kwargs)
  File "/home/user/.local/lib/python3.5/site-packages/django/core/management/commands/runserver.py", line 117, in inner_run
    self.check(display_num_errors=True)
  File "/home/user/.local/lib/python3.5/site-packages/django/core/management/base.py", line 390, in check
    include_deployment_checks=include_deployment_checks,
  File "/home/user/.local/lib/python3.5/site-packages/django/core/management/base.py", line 377, in _run_checks
    return checks.run_checks(**kwargs)
  File "/home/user/.local/lib/python3.5/site-packages/django/core/checks/registry.py", line 72, in run_checks
    new_errors = check(app_configs=app_configs)
  File "/home/user/.local/lib/python3.5/site-packages/django/core/checks/urls.py", line 40, in check_url_namespaces_unique
    all_namespaces = _load_all_namespaces(resolver)
  File "/home/user/.local/lib/python3.5/site-packages/django/core/checks/urls.py", line 57, in _load_all_namespaces
    url_patterns = getattr(resolver, 'url_patterns', [])
  File "/home/user/.local/lib/python3.5/site-packages/django/utils/functional.py", line 80, in __get__
    res = instance.__dict__[self.name] = self.func(instance)
  File "/home/user/.local/lib/python3.5/site-packages/django/urls/resolvers.py", line 584, in url_patterns
    patterns = getattr(self.urlconf_module, "urlpatterns", self.urlconf_module)
  File "/home/user/.local/lib/python3.5/site-packages/django/utils/functional.py", line 80, in __get__
    res = instance.__dict__[self.name] = self.func(instance)
  File "/home/user/.local/lib/python3.5/site-packages/django/urls/resolvers.py", line 577, in urlconf_module
    return import_module(self.urlconf_name)
  File "/usr/lib/python3.5/importlib/__init__.py", line 126, in import_module
    return _bootstrap._gcd_import(name[level:], package, level)
  File "<frozen importlib._bootstrap>", line 986, in _gcd_import
  File "<frozen importlib._bootstrap>", line 969, in _find_and_load
  File "<frozen importlib._bootstrap>", line 958, in _find_and_load_unlocked
  File "<frozen importlib._bootstrap>", line 673, in _load_unlocked
  File "<frozen importlib._bootstrap_external>", line 665, in exec_module
  File "<frozen importlib._bootstrap>", line 222, in _call_with_frames_removed
  File "/projects/book_store/Book_Store/Book_Store/urls.py", line 23, in <module>
    path('', views.home),
NameError: name 'views' is not defined

/projects/book_store/Book_Store/Book_Store/urls.py changed, reloading.
Performing system checks...

Watching for file changes with StatReloader
Exception in thread django-main-thread:
Traceback (most recent call last):
  File "/usr/lib/python3.5/threading.py", line 914, in _bootstrap_inner
    self.run()
  File "/usr/lib/python3.5/threading.py", line 862, in run
    self._target(*self._args, **self._kwargs)
  File "/home/user/.local/lib/python3.5/site-packages/django/utils/autoreload.py", line 54, in wrapper
    fn(*args, **kwargs)
  File "/home/user/.local/lib/python3.5/site-packages/django/core/management/commands/runserver.py", line 117, in inner_run
    self.check(display_num_errors=True)
  File "/home/user/.local/lib/python3.5/site-packages/django/core/management/base.py", line 390, in check
    include_deployment_checks=include_deployment_checks,
  File "/home/user/.local/lib/python3.5/site-packages/django/core/management/base.py", line 377, in _run_checks
    return checks.run_checks(**kwargs)
  File "/home/user/.local/lib/python3.5/site-packages/django/core/checks/registry.py", line 72, in run_checks
    new_errors = check(app_configs=app_configs)
  File "/home/user/.local/lib/python3.5/site-packages/django/core/checks/urls.py", line 13, in check_url_config
    return check_resolver(resolver)
  File "/home/user/.local/lib/python3.5/site-packages/django/core/checks/urls.py", line 23, in check_resolver
    return check_method()
  File "/home/user/.local/lib/python3.5/site-packages/django/urls/resolvers.py", line 399, in check
    for pattern in self.url_patterns:
  File "/home/user/.local/lib/python3.5/site-packages/django/utils/functional.py", line 80, in __get__
    res = instance.__dict__[self.name] = self.func(instance)
  File "/home/user/.local/lib/python3.5/site-packages/django/urls/resolvers.py", line 584, in url_patterns
    patterns = getattr(self.urlconf_module, "urlpatterns", self.urlconf_module)
  File "/home/user/.local/lib/python3.5/site-packages/django/utils/functional.py", line 80, in __get__
    res = instance.__dict__[self.name] = self.func(instance)
  File "/home/user/.local/lib/python3.5/site-packages/django/urls/resolvers.py", line 577, in urlconf_module
    return import_module(self.urlconf_name)
  File "/usr/lib/python3.5/importlib/__init__.py", line 126, in import_module
    return _bootstrap._gcd_import(name[level:], package, level)
  File "<frozen importlib._bootstrap>", line 986, in _gcd_import
  File "<frozen importlib._bootstrap>", line 969, in _find_and_load
  File "<frozen importlib._bootstrap>", line 958, in _find_and_load_unlocked
  File "<frozen importlib._bootstrap>", line 673, in _load_unlocked
  File "<frozen importlib._bootstrap_external>", line 665, in exec_module
  File "<frozen importlib._bootstrap>", line 222, in _call_with_frames_removed
  File "/projects/book_store/Book_Store/Book_Store/urls.py", line 23, in <module>
    path('', views.home),
AttributeError: module 'Book_Store.views' has no attribute 'home'

/projects/book_store/Book_Store/Book_Store/urls.py changed, reloading.
Performing system checks...

Watching for file changes with StatReloader
Watching for file changes with StatReloader
